<?xml version="1.0" ?>
<robot name="waddle_v2">
  <mujoco>
      <compiler meshdir="./assets" balanceinertia="true" discardvisual="false" fusestatic="true"/>
  </mujoco>
  <!-- Link trunk_assembly -->
  <link name="trunk_assembly">
    <inertial>
      <origin xyz="-0.0215141 0.00119061 0.0354003" rpy="0 0 0"/>
      <mass value="1.1678"/>
      <inertia ixx="0.00252715" ixy="0.000146105" ixz="0.000181039" iyy="0.00565527" iyz="-2.75948e-05" izz="0.00482046"/>
    </inertial>
    <!-- Part jetson_nano_baseplate -->
    <visual>
      <origin xyz="-0.072 0 0.0648909" rpy="0 -1.5708 0"/>
      <geometry>
        <mesh filename="package://assets/jetson_nano_baseplate.stl"/>
      </geometry>
      <material name="jetson_nano_baseplate_material">
        <color rgba="0.796078 0.823529 0.937255 1"/>
      </material>
    </visual>
    <!-- Part body_front -->
    <visual>
      <origin xyz="0.001 0 0.0648909" rpy="-0 0 0"/>
      <geometry>
        <mesh filename="package://assets/body_front.stl"/>
      </geometry>
      <material name="body_front_material">
        <color rgba="0.917647 0.917647 0.917647 1"/>
      </material>
    </visual>
    <!-- Part battery_enclosure -->
    <visual>
      <origin xyz="0.065 0.027 -0.0151091" rpy="0 -1.5708 0"/>
      <geometry>
        <mesh filename="package://assets/battery_enclosure.stl"/>
      </geometry>
      <material name="battery_enclosure_material">
        <color rgba="0.901961 0.901961 0.901961 1"/>
      </material>
    </visual>
    <!-- Part turnigy_3s_battery -->
    <visual>
      <origin xyz="0.027 -0.021 -0.0151091" rpy="-3.14159 -1.5708 0"/>
      <geometry>
        <mesh filename="package://assets/turnigy_3s_battery.stl"/>
      </geometry>
      <material name="turnigy_3s_battery_material">
        <color rgba="0.901961 0.901961 0.901961 1"/>
      </material>
    </visual>
    <!-- Part body_middle_bottom -->
    <visual>
      <origin xyz="-0.019 -0 0.0648909" rpy="-0 -0 0"/>
      <geometry>
        <mesh filename="package://assets/body_middle_bottom.stl"/>
      </geometry>
      <material name="body_middle_bottom_material">
        <color rgba="0.917647 0.917647 0.917647 1"/>
      </material>
    </visual>
    <!-- Part simplified_jetson_nano -->
    <visual>
      <origin xyz="-0.075 -0.0455645 -0.0129091" rpy="0 -1.5708 0"/>
      <geometry>
        <mesh filename="package://assets/simplified_jetson_nano.stl"/>
      </geometry>
      <material name="simplified_jetson_nano_material">
        <color rgba="0.901961 0.901961 0.901961 1"/>
      </material>
    </visual>
    <!-- Part switch -->
    <visual>
      <origin xyz="0.016 -0.0183295 -0.00648406" rpy="-1.5708 0 -0"/>
      <geometry>
        <mesh filename="package://assets/switch.stl"/>
      </geometry>
      <material name="switch_material">
        <color rgba="0.972549 0.529412 0.00392157 1"/>
      </material>
    </visual>
    <!-- Part body_middle_top -->
    <visual>
      <origin xyz="-0.019 0 0.0648909" rpy="-0 -0 0"/>
      <geometry>
        <mesh filename="package://assets/body_middle_top.stl"/>
      </geometry>
      <material name="body_middle_top_material">
        <color rgba="0.917647 0.917647 0.917647 1"/>
      </material>
    </visual>
    <!-- Part body_back -->
    <visual>
      <origin xyz="-0.019 0 0.0648909" rpy="-0 -0 0"/>
      <geometry>
        <mesh filename="package://assets/body_back.stl"/>
      </geometry>
      <material name="body_back_material">
        <color rgba="0.917647 0.917647 0.917647 1"/>
      </material>
    </visual>
    <!-- Part bno055 -->
    <visual>
      <origin xyz="-0.040705 -1.715e-09 0.0917909" rpy="-3.14159 0 3.14159"/>
      <geometry>
        <mesh filename="package://assets/bno055.stl"/>
      </geometry>
      <material name="bno055_material">
        <color rgba="0.615686 0.811765 0.929412 1"/>
      </material>
    </visual>
    <!-- Part roll_bearing -->
    <visual>
      <origin xyz="-0.019 -0 0.0648909" rpy="-0 -0 -0"/>
      <geometry>
        <mesh filename="package://assets/roll_bearing.stl"/>
      </geometry>
      <material name="roll_bearing_material">
        <color rgba="0.6 0.6 0.6 1"/>
      </material>
    </visual>
    <!-- Part trunk_bottom -->
    <visual>
      <origin xyz="-0.019 0 0.0648909" rpy="-0 -0 0"/>
      <geometry>
        <mesh filename="package://assets/trunk_bottom.stl"/>
      </geometry>
      <material name="trunk_bottom_material">
        <color rgba="0.180392 0.180392 0.180392 1"/>
      </material>
    </visual>
    <!-- Part trunk_top -->
    <visual>
      <origin xyz="-0.019 -0 0.0648909" rpy="-0 0 -0"/>
      <geometry>
        <mesh filename="package://assets/trunk_top.stl"/>
      </geometry>
      <material name="trunk_top_material">
        <color rgba="0.180392 0.180392 0.180392 1"/>
      </material>
    </visual>
    <!-- Part board -->
    <visual>
      <origin xyz="-0.06371 0.0171628 0.0404109" rpy="-3.14159 1.5708 0"/>
      <geometry>
        <mesh filename="package://assets/board.stl"/>
      </geometry>
      <material name="board_material">
        <color rgba="0 0.501961 0 1"/>
      </material>
    </visual>
    <!-- Part roll_bearing_2 -->
    <visual>
      <origin xyz="-0.019 -0.07 0.0648909" rpy="-0 -0 -0"/>
      <geometry>
        <mesh filename="package://assets/roll_bearing.stl"/>
      </geometry>
      <material name="roll_bearing_2_material">
        <color rgba="0.6 0.6 0.6 1"/>
      </material>
    </visual>
    <!-- Part pdb_xt60 -->
    <visual>
      <origin xyz="-0.04661 -0.018 0.00179094" rpy="-1.5708 0 1.5708"/>
      <geometry>
        <mesh filename="package://assets/pdb_xt60.stl"/>
      </geometry>
      <material name="pdb_xt60_material">
        <color rgba="0.615686 0.811765 0.929412 1"/>
      </material>
    </visual>
    <!-- Part wj_wk00_0123middlecase_56 -->
    <visual>
      <origin xyz="0.001 0.0097 0.0645009" rpy="0 1.5708 0"/>
      <geometry>
        <mesh filename="package://assets/wj_wk00_0123middlecase_56.stl"/>
      </geometry>
      <material name="wj_wk00_0123middlecase_56_material">
        <color rgba="0.247059 0.243137 0.243137 1"/>
      </material>
    </visual>
    <!-- Part drive_palonier -->
    <visual>
      <origin xyz="0.001 0.0097 0.0645009" rpy="0 1.5708 0"/>
      <geometry>
        <mesh filename="package://assets/drive_palonier.stl"/>
      </geometry>
      <material name="drive_palonier_material">
        <color rgba="0.623529 0.666667 0.701961 1"/>
      </material>
    </visual>
    <!-- Part wj_wk00_0124bottomcase_45 -->
    <visual>
      <origin xyz="0.001 0.0097 0.0645009" rpy="0 1.5708 0"/>
      <geometry>
        <mesh filename="package://assets/wj_wk00_0124bottomcase_45.stl"/>
      </geometry>
      <material name="wj_wk00_0124bottomcase_45_material">
        <color rgba="0.247059 0.243137 0.243137 1"/>
      </material>
    </visual>
    <!-- Part wj_wk00_0122topcabinetcase_95 -->
    <visual>
      <origin xyz="0.001 0.0097 0.0645009" rpy="0 1.5708 0"/>
      <geometry>
        <mesh filename="package://assets/wj_wk00_0122topcabinetcase_95.stl"/>
      </geometry>
      <material name="wj_wk00_0122topcabinetcase_95_material">
        <color rgba="0.247059 0.243137 0.243137 1"/>
      </material>
    </visual>
    <!-- Part passive_palonier -->
    <visual>
      <origin xyz="0.001 0.0126 0.0645009" rpy="0 1.5708 0"/>
      <geometry>
        <mesh filename="package://assets/passive_palonier.stl"/>
      </geometry>
      <material name="passive_palonier_material">
        <color rgba="0.623529 0.666667 0.701961 1"/>
      </material>
    </visual>
    <!-- Part wj_wk00_0123middlecase_56_2 -->
    <visual>
      <origin xyz="-0.0445 -0.035 0.0553909" rpy="-1.5708 0 3.14159"/>
      <geometry>
        <mesh filename="package://assets/wj_wk00_0123middlecase_56.stl"/>
      </geometry>
      <material name="wj_wk00_0123middlecase_56_2_material">
        <color rgba="0.247059 0.243137 0.243137 1"/>
      </material>
    </visual>
    <!-- Part drive_palonier_2 -->
    <visual>
      <origin xyz="-0.0445 -0.035 0.0553909" rpy="-1.5708 0 3.14159"/>
      <geometry>
        <mesh filename="package://assets/drive_palonier.stl"/>
      </geometry>
      <material name="drive_palonier_2_material">
        <color rgba="0.623529 0.666667 0.701961 1"/>
      </material>
    </visual>
    <!-- Part wj_wk00_0124bottomcase_45_2 -->
    <visual>
      <origin xyz="-0.0445 -0.035 0.0553909" rpy="-1.5708 0 3.14159"/>
      <geometry>
        <mesh filename="package://assets/wj_wk00_0124bottomcase_45.stl"/>
      </geometry>
      <material name="wj_wk00_0124bottomcase_45_2_material">
        <color rgba="0.247059 0.243137 0.243137 1"/>
      </material>
    </visual>
    <!-- Part wj_wk00_0122topcabinetcase_95_2 -->
    <visual>
      <origin xyz="-0.0445 -0.035 0.0553909" rpy="-1.5708 0 3.14159"/>
      <geometry>
        <mesh filename="package://assets/wj_wk00_0122topcabinetcase_95.stl"/>
      </geometry>
      <material name="wj_wk00_0122topcabinetcase_95_2_material">
        <color rgba="0.247059 0.243137 0.243137 1"/>
      </material>
    </visual>
    <!-- Part passive_palonier_2 -->
    <visual>
      <origin xyz="-0.0445 -0.035 0.0524909" rpy="-1.5708 0 3.14159"/>
      <geometry>
        <mesh filename="package://assets/passive_palonier.stl"/>
      </geometry>
      <material name="passive_palonier_2_material">
        <color rgba="0.623529 0.666667 0.701961 1"/>
      </material>
    </visual>
    <!-- Part wj_wk00_0123middlecase_56_3 -->
    <visual>
      <origin xyz="-0.0445 0.035 0.0553909" rpy="-1.5708 0 3.14159"/>
      <geometry>
        <mesh filename="package://assets/wj_wk00_0123middlecase_56.stl"/>
      </geometry>
      <material name="wj_wk00_0123middlecase_56_3_material">
        <color rgba="0.247059 0.243137 0.243137 1"/>
      </material>
    </visual>
    <!-- Part drive_palonier_3 -->
    <visual>
      <origin xyz="-0.0445 0.035 0.0553909" rpy="-1.5708 0 3.14159"/>
      <geometry>
        <mesh filename="package://assets/drive_palonier.stl"/>
      </geometry>
      <material name="drive_palonier_3_material">
        <color rgba="0.623529 0.666667 0.701961 1"/>
      </material>
    </visual>
    <!-- Part wj_wk00_0124bottomcase_45_3 -->
    <visual>
      <origin xyz="-0.0445 0.035 0.0553909" rpy="-1.5708 0 3.14159"/>
      <geometry>
        <mesh filename="package://assets/wj_wk00_0124bottomcase_45.stl"/>
      </geometry>
      <material name="wj_wk00_0124bottomcase_45_3_material">
        <color rgba="0.247059 0.243137 0.243137 1"/>
      </material>
    </visual>
    <!-- Part wj_wk00_0122topcabinetcase_95_3 -->
    <visual>
      <origin xyz="-0.0445 0.035 0.0553909" rpy="-1.5708 0 3.14159"/>
      <geometry>
        <mesh filename="package://assets/wj_wk00_0122topcabinetcase_95.stl"/>
      </geometry>
      <material name="wj_wk00_0122topcabinetcase_95_3_material">
        <color rgba="0.247059 0.243137 0.243137 1"/>
      </material>
    </visual>
    <!-- Part passive_palonier_3 -->
    <visual>
      <origin xyz="-0.0445 0.035 0.0524909" rpy="-1.5708 0 3.14159"/>
      <geometry>
        <mesh filename="package://assets/passive_palonier.stl"/>
      </geometry>
      <material name="passive_palonier_3_material">
        <color rgba="0.623529 0.666667 0.701961 1"/>
      </material>
    </visual>
  </link>
  <!-- Frame trunk (dummy link + fixed joint) -->
  <link name="trunk">
    <origin xyz="0 0 0" rpy="0 -0 0"/>
    <inertial>
      <origin xyz="0 0 0" rpy="0 0 0"/>
      <mass value="1e-9"/>
      <inertia ixx="0" ixy="0" ixz="0" iyy="0" iyz="0" izz="0"/>
    </inertial>
  </link>
  <joint name="trunk_frame" type="fixed">
    <origin xyz="-0.024 -0 0.0881909" rpy="-0 -0 -0"/>
    <parent link="trunk_assembly"/>
    <child link="trunk"/>
    <axis xyz="0 0 0"/>
  </joint>
  <!-- Frame imu (dummy link + fixed joint) -->
  <link name="imu">
    <origin xyz="0 0 0" rpy="0 -0 0"/>
    <inertial>
      <origin xyz="0 0 0" rpy="0 0 0"/>
      <mass value="1e-9"/>
      <inertia ixx="0" ixy="0" ixz="0" iyy="0" iyz="0" izz="0"/>
    </inertial>
  </link>
  <joint name="imu_frame" type="fixed">
    <origin xyz="-0.040705 -1.715e-09 0.0862909" rpy="-0 -0 -0"/>
    <parent link="trunk_assembly"/>
    <child link="imu"/>
    <axis xyz="0 0 0"/>
  </joint>
  <!-- Link hip_roll_assembly -->
  <link name="hip_roll_assembly">
    <inertial>
      <origin xyz="0.000795081 -5.46541e-06 -0.03306" rpy="0 0 0"/>
      <mass value="0.06648"/>
      <inertia ixx="2.44411e-05" ixy="2.357e-09" ixz="-3.81059e-07" iyy="2.81818e-05" iyz="-7.5e-09" izz="1.42687e-05"/>
    </inertial>
    <!-- Part roll_motor_bottom -->
    <visual>
      <origin xyz="-0 -0.035 0.01905" rpy="-0 0 -0"/>
      <geometry>
        <mesh filename="package://assets/roll_motor_bottom.stl"/>
      </geometry>
      <material name="roll_motor_bottom_material">
        <color rgba="0.647059 0.647059 0.647059 1"/>
      </material>
    </visual>
    <!-- Part roll_motor_top -->
    <visual>
      <origin xyz="0 -0.035 0.01905" rpy="0 -0 0"/>
      <geometry>
        <mesh filename="package://assets/roll_motor_top.stl"/>
      </geometry>
      <material name="roll_motor_top_material">
        <color rgba="0.901961 0.901961 0.901961 1"/>
      </material>
    </visual>
    <!-- Part wj_wk00_0123middlecase_56_4 -->
    <visual>
      <origin xyz="0.0096 0 -0.020515" rpy="-1.5708 -1.5708 0"/>
      <geometry>
        <mesh filename="package://assets/wj_wk00_0123middlecase_56.stl"/>
      </geometry>
      <material name="wj_wk00_0123middlecase_56_4_material">
        <color rgba="0.247059 0.243137 0.243137 1"/>
      </material>
    </visual>
    <!-- Part drive_palonier_4 -->
    <visual>
      <origin xyz="0.0096 0 -0.020515" rpy="-1.5708 -1.5708 0"/>
      <geometry>
        <mesh filename="package://assets/drive_palonier.stl"/>
      </geometry>
      <material name="drive_palonier_4_material">
        <color rgba="0.623529 0.666667 0.701961 1"/>
      </material>
    </visual>
    <!-- Part wj_wk00_0124bottomcase_45_4 -->
    <visual>
      <origin xyz="0.0096 0 -0.020515" rpy="-1.5708 -1.5708 0"/>
      <geometry>
        <mesh filename="package://assets/wj_wk00_0124bottomcase_45.stl"/>
      </geometry>
      <material name="wj_wk00_0124bottomcase_45_4_material">
        <color rgba="0.247059 0.243137 0.243137 1"/>
      </material>
    </visual>
    <!-- Part wj_wk00_0122topcabinetcase_95_4 -->
    <visual>
      <origin xyz="0.0096 0 -0.020515" rpy="-1.5708 -1.5708 0"/>
      <geometry>
        <mesh filename="package://assets/wj_wk00_0122topcabinetcase_95.stl"/>
      </geometry>
      <material name="wj_wk00_0122topcabinetcase_95_4_material">
        <color rgba="0.247059 0.243137 0.243137 1"/>
      </material>
    </visual>
    <!-- Part passive_palonier_4 -->
    <visual>
      <origin xyz="0.0125 0 -0.020515" rpy="-1.5708 -1.5708 0"/>
      <geometry>
        <mesh filename="package://assets/passive_palonier.stl"/>
      </geometry>
      <material name="passive_palonier_4_material">
        <color rgba="0.623529 0.666667 0.701961 1"/>
      </material>
    </visual>
  </link>
  <!-- Link left_roll_to_pitch_assembly -->
  <link name="left_roll_to_pitch_assembly">
    <inertial>
      <origin xyz="0.0507497 -0.000407512 0.0204377" rpy="0 0 0"/>
      <mass value="0.07516"/>
      <inertia ixx="2.52682e-05" ixy="1.22744e-07" ixz="-7.32857e-07" iyy="4.15738e-05" iyz="-1.05692e-07" izz="2.82869e-05"/>
    </inertial>
    <!-- Part left_roll_to_pitch -->
    <visual>
      <origin xyz="-0.035 -0.065 0.01905" rpy="1.5708 1.5708 0"/>
      <geometry>
        <mesh filename="package://assets/left_roll_to_pitch.stl"/>
      </geometry>
      <material name="left_roll_to_pitch_material">
        <color rgba="0.909804 0.572549 0.164706 1"/>
      </material>
    </visual>
    <!-- Part wj_wk00_0123middlecase_56_5 -->
    <visual>
      <origin xyz="0.0647 0 0.00961" rpy="1.5708 1.5708 0"/>
      <geometry>
        <mesh filename="package://assets/wj_wk00_0123middlecase_56.stl"/>
      </geometry>
      <material name="wj_wk00_0123middlecase_56_5_material">
        <color rgba="0.247059 0.243137 0.243137 1"/>
      </material>
    </visual>
    <!-- Part drive_palonier_5 -->
    <visual>
      <origin xyz="0.0647 0 0.00961" rpy="1.5708 1.5708 0"/>
      <geometry>
        <mesh filename="package://assets/drive_palonier.stl"/>
      </geometry>
      <material name="drive_palonier_5_material">
        <color rgba="0.623529 0.666667 0.701961 1"/>
      </material>
    </visual>
    <!-- Part wj_wk00_0124bottomcase_45_5 -->
    <visual>
      <origin xyz="0.0647 0 0.00961" rpy="1.5708 1.5708 0"/>
      <geometry>
        <mesh filename="package://assets/wj_wk00_0124bottomcase_45.stl"/>
      </geometry>
      <material name="wj_wk00_0124bottomcase_45_5_material">
        <color rgba="0.247059 0.243137 0.243137 1"/>
      </material>
    </visual>
    <!-- Part wj_wk00_0122topcabinetcase_95_5 -->
    <visual>
      <origin xyz="0.0647 0 0.00961" rpy="1.5708 1.5708 0"/>
      <geometry>
        <mesh filename="package://assets/wj_wk00_0122topcabinetcase_95.stl"/>
      </geometry>
      <material name="wj_wk00_0122topcabinetcase_95_5_material">
        <color rgba="0.247059 0.243137 0.243137 1"/>
      </material>
    </visual>
    <!-- Part passive_palonier_5 -->
    <visual>
      <origin xyz="0.0676 0 0.00961" rpy="1.5708 1.5708 0"/>
      <geometry>
        <mesh filename="package://assets/passive_palonier.stl"/>
      </geometry>
      <material name="passive_palonier_5_material">
        <color rgba="0.623529 0.666667 0.701961 1"/>
      </material>
    </visual>
  </link>
  <!-- Link knee_and_ankle_assembly -->
  <link name="knee_and_ankle_assembly">
    <inertial>
      <origin xyz="0.00253369 -0.0390636 0.0102776" rpy="0 0 0"/>
      <mass value="0.12407"/>
      <inertia ixx="0.000211406" ixy="-2.68706e-05" ixz="3.81906e-06" iyy="7.83759e-05" iyz="2.08009e-05" izz="0.000225619"/>
    </inertial>
    <!-- Part left_cache -->
    <visual>
      <origin xyz="0.01606 0.065 0.10915" rpy="-1.5708 0 -0"/>
      <geometry>
        <mesh filename="package://assets/left_cache.stl"/>
      </geometry>
      <material name="left_cache_material">
        <color rgba="0.917647 0.917647 0.917647 1"/>
      </material>
    </visual>
    <!-- Part leg_spacer -->
    <visual>
      <origin xyz="0.01606 0.14365 0.10925" rpy="-1.5708 -0 -0"/>
      <geometry>
        <mesh filename="package://assets/leg_spacer.stl"/>
      </geometry>
      <material name="leg_spacer_material">
        <color rgba="0.647059 0.647059 0.647059 1"/>
      </material>
    </visual>
    <!-- Part left_knee_to_ankle_right_sheet -->
    <visual>
      <origin xyz="0.01606 0.14365 0.10915" rpy="-1.5708 -0 -0"/>
      <geometry>
        <mesh filename="package://assets/left_knee_to_ankle_right_sheet.stl"/>
      </geometry>
      <material name="left_knee_to_ankle_right_sheet_material">
        <color rgba="0.223529 0.219608 0.219608 1"/>
      </material>
    </visual>
    <!-- Part left_knee_to_ankle_left_sheet -->
    <visual>
      <origin xyz="0.01606 0.14365 0.10915" rpy="-1.5708 0 0"/>
      <geometry>
        <mesh filename="package://assets/left_knee_to_ankle_left_sheet.stl"/>
      </geometry>
      <material name="left_knee_to_ankle_left_sheet_material">
        <color rgba="0.223529 0.219608 0.219608 1"/>
      </material>
    </visual>
    <!-- Part wj_wk00_0123middlecase_56_6 -->
    <visual>
      <origin xyz="-0 -0.05315 0.00955" rpy="-1.5708 -0 1.5708"/>
      <geometry>
        <mesh filename="package://assets/wj_wk00_0123middlecase_56.stl"/>
      </geometry>
      <material name="wj_wk00_0123middlecase_56_6_material">
        <color rgba="0.247059 0.243137 0.243137 1"/>
      </material>
    </visual>
    <!-- Part drive_palonier_6 -->
    <visual>
      <origin xyz="-0 -0.05315 0.00955" rpy="-1.5708 -0 1.5708"/>
      <geometry>
        <mesh filename="package://assets/drive_palonier.stl"/>
      </geometry>
      <material name="drive_palonier_6_material">
        <color rgba="0.623529 0.666667 0.701961 1"/>
      </material>
    </visual>
    <!-- Part wj_wk00_0124bottomcase_45_6 -->
    <visual>
      <origin xyz="-0 -0.05315 0.00955" rpy="-1.5708 -0 1.5708"/>
      <geometry>
        <mesh filename="package://assets/wj_wk00_0124bottomcase_45.stl"/>
      </geometry>
      <material name="wj_wk00_0124bottomcase_45_6_material">
        <color rgba="0.247059 0.243137 0.243137 1"/>
      </material>
    </visual>
    <!-- Part wj_wk00_0122topcabinetcase_95_6 -->
    <visual>
      <origin xyz="-0 -0.05315 0.00955" rpy="-1.5708 -0 1.5708"/>
      <geometry>
        <mesh filename="package://assets/wj_wk00_0122topcabinetcase_95.stl"/>
      </geometry>
      <material name="wj_wk00_0122topcabinetcase_95_6_material">
        <color rgba="0.247059 0.243137 0.243137 1"/>
      </material>
    </visual>
    <!-- Part passive_palonier_6 -->
    <visual>
      <origin xyz="0 -0.05315 0.00665" rpy="-1.5708 -0 1.5708"/>
      <geometry>
        <mesh filename="package://assets/passive_palonier.stl"/>
      </geometry>
      <material name="passive_palonier_6_material">
        <color rgba="0.623529 0.666667 0.701961 1"/>
      </material>
    </visual>
  </link>
  <!-- Link knee_and_ankle_assembly_2 -->
  <link name="knee_and_ankle_assembly_2">
    <inertial>
      <origin xyz="5.01859e-06 -0.0577465 0.0181136" rpy="0 0 0"/>
      <mass value="0.07259"/>
      <inertia ixx="4.99575e-05" ixy="1.0382e-08" ixz="2.252e-09" iyy="1.87273e-05" iyz="8.8105e-08" izz="4.23932e-05"/>
    </inertial>
    <!-- Part leg_spacer_2 -->
    <visual>
      <origin xyz="0.01606 0.14365 0.10925" rpy="-1.5708 -0 -0"/>
      <geometry>
        <mesh filename="package://assets/leg_spacer.stl"/>
      </geometry>
      <material name="leg_spacer_2_material">
        <color rgba="0.647059 0.647059 0.647059 1"/>
      </material>
    </visual>
    <!-- Part left_knee_to_ankle_right_sheet_2 -->
    <visual>
      <origin xyz="0.01606 0.14365 0.10915" rpy="-1.5708 -0 0"/>
      <geometry>
        <mesh filename="package://assets/left_knee_to_ankle_right_sheet.stl"/>
      </geometry>
      <material name="left_knee_to_ankle_right_sheet_2_material">
        <color rgba="0.223529 0.219608 0.219608 1"/>
      </material>
    </visual>
    <!-- Part left_knee_to_ankle_left_sheet_2 -->
    <visual>
      <origin xyz="0.01606 0.14365 0.10915" rpy="-1.5708 0 0"/>
      <geometry>
        <mesh filename="package://assets/left_knee_to_ankle_left_sheet.stl"/>
      </geometry>
      <material name="left_knee_to_ankle_left_sheet_2_material">
        <color rgba="0.223529 0.219608 0.219608 1"/>
      </material>
    </visual>
    <!-- Part wj_wk00_0123middlecase_56_7 -->
    <visual>
      <origin xyz="0 -0.05315 0.00955" rpy="-1.5708 0 1.5708"/>
      <geometry>
        <mesh filename="package://assets/wj_wk00_0123middlecase_56.stl"/>
      </geometry>
      <material name="wj_wk00_0123middlecase_56_7_material">
        <color rgba="0.247059 0.243137 0.243137 1"/>
      </material>
    </visual>
    <!-- Part drive_palonier_7 -->
    <visual>
      <origin xyz="0 -0.05315 0.00955" rpy="-1.5708 0 1.5708"/>
      <geometry>
        <mesh filename="package://assets/drive_palonier.stl"/>
      </geometry>
      <material name="drive_palonier_7_material">
        <color rgba="0.623529 0.666667 0.701961 1"/>
      </material>
    </visual>
    <!-- Part wj_wk00_0124bottomcase_45_7 -->
    <visual>
      <origin xyz="0 -0.05315 0.00955" rpy="-1.5708 0 1.5708"/>
      <geometry>
        <mesh filename="package://assets/wj_wk00_0124bottomcase_45.stl"/>
      </geometry>
      <material name="wj_wk00_0124bottomcase_45_7_material">
        <color rgba="0.247059 0.243137 0.243137 1"/>
      </material>
    </visual>
    <!-- Part wj_wk00_0122topcabinetcase_95_7 -->
    <visual>
      <origin xyz="0 -0.05315 0.00955" rpy="-1.5708 0 1.5708"/>
      <geometry>
        <mesh filename="package://assets/wj_wk00_0122topcabinetcase_95.stl"/>
      </geometry>
      <material name="wj_wk00_0122topcabinetcase_95_7_material">
        <color rgba="0.247059 0.243137 0.243137 1"/>
      </material>
    </visual>
    <!-- Part passive_palonier_7 -->
    <visual>
      <origin xyz="-0 -0.05315 0.00665" rpy="-1.5708 0 1.5708"/>
      <geometry>
        <mesh filename="package://assets/passive_palonier.stl"/>
      </geometry>
      <material name="passive_palonier_7_material">
        <color rgba="0.623529 0.666667 0.701961 1"/>
      </material>
    </visual>
  </link>
  <!-- Link foot_assembly -->
  <link name="foot_assembly">
    <inertial>
      <origin xyz="0.0110718 -0.0246608 0.0190626" rpy="0 0 0"/>
      <mass value="0.07524"/>
      <inertia ixx="1.87482e-05" ixy="1.58839e-06" ixz="-6.524e-09" iyy="6.74427e-05" iyz="5.6739e-08" izz="6.061e-05"/>
    </inertial>
    <!-- Part foot_side -->
    <visual>
      <origin xyz="0.01606 0.2223 0.10905" rpy="-1.5708 0 0"/>
      <geometry>
        <mesh filename="package://assets/foot_side.stl"/>
      </geometry>
      <material name="foot_side_material">
        <color rgba="0.980392 0.713725 0.00392157 1"/>
      </material>
    </visual>
    <!-- Part foot_bottom_tpu -->
    <visual>
      <origin xyz="0.01656 0.2228 0.10955" rpy="-1.5708 0 0"/>
      <geometry>
        <mesh filename="package://assets/foot_bottom_tpu.stl"/>
      </geometry>
      <material name="foot_bottom_tpu_material">
        <color rgba="0.305882 0.298039 0.278431 1"/>
      </material>
    </visual>
    <collision>
      <origin xyz="0.01656 0.2228 0.10955" rpy="-1.5708 0 0"/>
      <geometry>
        <mesh filename="package://assets/foot_bottom_tpu.stl"/>
      </geometry>
    </collision>
    <!-- Part foot_bottom_pla -->
    <visual>
      <origin xyz="0.01656 0.2228 0.10955" rpy="-1.5708 0 0"/>
      <geometry>
        <mesh filename="package://assets/foot_bottom_pla.stl"/>
      </geometry>
      <material name="foot_bottom_pla_material">
        <color rgba="0.305882 0.298039 0.278431 1"/>
      </material>
    </visual>
    <!-- Part foot_top -->
    <visual>
      <origin xyz="0.01606 0.2223 0.10905" rpy="-1.5708 0 0"/>
      <geometry>
        <mesh filename="package://assets/foot_top.stl"/>
      </geometry>
      <material name="foot_top_material">
        <color rgba="0.980392 0.713725 0.00392157 1"/>
      </material>
    </visual>
  </link>
  <!-- Frame left_foot (dummy link + fixed joint) -->
  <link name="left_foot">
    <origin xyz="0 0 0" rpy="0 -0 0"/>
    <inertial>
      <origin xyz="0 0 0" rpy="0 0 0"/>
      <mass value="1e-9"/>
      <inertia ixx="0" ixy="0" ixz="0" iyy="0" iyz="0" izz="0"/>
    </inertial>
  </link>
  <joint name="left_foot_frame" type="fixed">
    <origin xyz="0.0005 -0.036225 0.01955" rpy="-1.5708 0 0"/>
    <parent link="foot_assembly"/>
    <child link="left_foot"/>
    <axis xyz="0 0 0"/>
  </joint>
  <!-- Joint from knee_and_ankle_assembly_2 to foot_assembly -->
  <joint name="left_ankle" type="revolute">
    <origin xyz="0 -0.07865 0.0001" rpy="0 0 0"/>
    <parent link="knee_and_ankle_assembly_2"/>
    <child link="foot_assembly"/>
    <axis xyz="0 0 1"/>
    <limit effort="100" velocity="100" lower="-1.5708" upper="1.5708"/>
    <joint_properties friction="0.0"/>
  </joint>
  <!-- Joint from knee_and_ankle_assembly to knee_and_ankle_assembly_2 -->
  <joint name="left_knee" type="revolute">
    <origin xyz="0 -0.07865 0.0001" rpy="0 0 0"/>
    <parent link="knee_and_ankle_assembly"/>
    <child link="knee_and_ankle_assembly_2"/>
    <axis xyz="0 0 1"/>
    <limit effort="100" velocity="100" lower="-1.5708" upper="1.5708"/>
    <joint_properties friction="0.0"/>
  </joint>
  <!-- Joint from left_roll_to_pitch_assembly to knee_and_ankle_assembly -->
  <joint name="left_hip_pitch" type="revolute">
    <origin xyz="0.07415 0 0.03511" rpy="3.14159 1.5708 0"/>
    <parent link="left_roll_to_pitch_assembly"/>
    <child link="knee_and_ankle_assembly"/>
    <axis xyz="0 0 1"/>
    <limit effort="100" velocity="100" lower="-1.2217" upper="0.5236"/>
    <joint_properties friction="0.0"/>
  </joint>
  <!-- Joint from hip_roll_assembly to left_roll_to_pitch_assembly -->
  <joint name="left_hip_roll" type="revolute">
    <origin xyz="0.01905 0 -0.046015" rpy="-1.5708 0 1.5708"/>
    <parent link="hip_roll_assembly"/>
    <child link="left_roll_to_pitch_assembly"/>
    <axis xyz="0 0 1"/>
    <limit effort="100" velocity="100" lower="-0.436332" upper="0.436332"/>
    <joint_properties friction="0.0"/>
  </joint>
  <!-- Joint from trunk_assembly to hip_roll_assembly -->
  <joint name="left_hip_yaw" type="revolute">
    <origin xyz="-0.019 0.035 0.0459409" rpy="0 0 0"/>
    <parent link="trunk_assembly"/>
    <child link="hip_roll_assembly"/>
    <axis xyz="0 0 1"/>
    <limit effort="100" velocity="100" lower="-0.523599" upper="0.523599"/>
    <joint_properties friction="0.0"/>
  </joint>
  <!-- Link neck_pitch_assembly -->
  <link name="neck_pitch_assembly">
    <inertial>
      <origin xyz="-5.63137e-06 0.0492968 0.0181786" rpy="0 0 0"/>
      <mass value="0.06618"/>
      <inertia ixx="3.49456e-05" ixy="8.756e-09" ixz="-2.156e-09" iyy="1.70231e-05" iyz="-1.8519e-08" izz="2.80043e-05"/>
    </inertial>
    <!-- Part neck_left_sheet -->
    <visual>
      <origin xyz="-0.02 -0.02511 0.01905" rpy="-1.5708 -0 -0"/>
      <geometry>
        <mesh filename="package://assets/neck_left_sheet.stl"/>
      </geometry>
      <material name="neck_left_sheet_material">
        <color rgba="0.223529 0.219608 0.219608 1"/>
      </material>
    </visual>
    <!-- Part neck_right_sheet -->
    <visual>
      <origin xyz="-0.02 -0.02511 0.01905" rpy="-1.5708 0 -0"/>
      <geometry>
        <mesh filename="package://assets/neck_right_sheet.stl"/>
      </geometry>
      <material name="neck_right_sheet_material">
        <color rgba="0.223529 0.219608 0.219608 1"/>
      </material>
    </visual>
    <!-- Part wj_wk00_0123middlecase_56_8 -->
    <visual>
      <origin xyz="0 0.0405 0.00945" rpy="-1.5708 -0 -1.5708"/>
      <geometry>
        <mesh filename="package://assets/wj_wk00_0123middlecase_56.stl"/>
      </geometry>
      <material name="wj_wk00_0123middlecase_56_8_material">
        <color rgba="0.247059 0.243137 0.243137 1"/>
      </material>
    </visual>
    <!-- Part drive_palonier_8 -->
    <visual>
      <origin xyz="0 0.0405 0.00945" rpy="-1.5708 -0 -1.5708"/>
      <geometry>
        <mesh filename="package://assets/drive_palonier.stl"/>
      </geometry>
      <material name="drive_palonier_8_material">
        <color rgba="0.623529 0.666667 0.701961 1"/>
      </material>
    </visual>
    <!-- Part wj_wk00_0124bottomcase_45_8 -->
    <visual>
      <origin xyz="0 0.0405 0.00945" rpy="-1.5708 -0 -1.5708"/>
      <geometry>
        <mesh filename="package://assets/wj_wk00_0124bottomcase_45.stl"/>
      </geometry>
      <material name="wj_wk00_0124bottomcase_45_8_material">
        <color rgba="0.247059 0.243137 0.243137 1"/>
      </material>
    </visual>
    <!-- Part wj_wk00_0122topcabinetcase_95_8 -->
    <visual>
      <origin xyz="0 0.0405 0.00945" rpy="-1.5708 -0 -1.5708"/>
      <geometry>
        <mesh filename="package://assets/wj_wk00_0122topcabinetcase_95.stl"/>
      </geometry>
      <material name="wj_wk00_0122topcabinetcase_95_8_material">
        <color rgba="0.247059 0.243137 0.243137 1"/>
      </material>
    </visual>
    <!-- Part passive_palonier_8 -->
    <visual>
      <origin xyz="0 0.0405 0.00655" rpy="-1.5708 -0 -1.5708"/>
      <geometry>
        <mesh filename="package://assets/passive_palonier.stl"/>
      </geometry>
      <material name="passive_palonier_8_material">
        <color rgba="0.623529 0.666667 0.701961 1"/>
      </material>
    </visual>
  </link>
  <!-- Link head_pitch_to_yaw -->
  <link name="head_pitch_to_yaw">
    <inertial>
      <origin xyz="-0.00766247 0.026015 0.0186681" rpy="0 0 0"/>
      <mass value="0.0169378"/>
      <inertia ixx="9.43036e-06" ixy="1.35195e-06" ixz="3.059e-08" iyy="4.64763e-06" iyz="-8.428e-08" izz="8.02915e-06"/>
    </inertial>
    <!-- Part head_pitch_to_yaw -->
    <visual>
      <origin xyz="-0.02 -0.09111 0.01905" rpy="-1.5708 0 -0"/>
      <geometry>
        <mesh filename="package://assets/head_pitch_to_yaw.stl"/>
      </geometry>
      <material name="head_pitch_to_yaw_material">
        <color rgba="0.4 0.4 0.4 1"/>
      </material>
    </visual>
  </link>
  <!-- Link neck_yaw_assembly -->
  <link name="neck_yaw_assembly">
    <inertial>
      <origin xyz="0.00412907 3.95745e-06 -0.0222828" rpy="0 0 0"/>
      <mass value="0.0918099"/>
      <inertia ixx="3.11706e-05" ixy="4.294e-09" ixz="-4.41251e-06" iyy="6.94935e-05" iyz="-3.82e-09" izz="7.04025e-05"/>
    </inertial>
    <!-- Part head_yaw_to_roll -->
    <visual>
      <origin xyz="-0.02 0 -0.14821" rpy="0 -0 -0"/>
      <geometry>
        <mesh filename="package://assets/head_yaw_to_roll.stl"/>
      </geometry>
      <material name="head_yaw_to_roll_material">
        <color rgba="0.647059 0.647059 0.647059 1"/>
      </material>
    </visual>
    <!-- Part wj_wk00_0123middlecase_56_9 -->
    <visual>
      <origin xyz="0.0255 0 -0.00945" rpy="1.5708 0 0"/>
      <geometry>
        <mesh filename="package://assets/wj_wk00_0123middlecase_56.stl"/>
      </geometry>
      <material name="wj_wk00_0123middlecase_56_9_material">
        <color rgba="0.247059 0.243137 0.243137 1"/>
      </material>
    </visual>
    <!-- Part drive_palonier_9 -->
    <visual>
      <origin xyz="0.0255 0 -0.00945" rpy="1.5708 0 0"/>
      <geometry>
        <mesh filename="package://assets/drive_palonier.stl"/>
      </geometry>
      <material name="drive_palonier_9_material">
        <color rgba="0.623529 0.666667 0.701961 1"/>
      </material>
    </visual>
    <!-- Part wj_wk00_0124bottomcase_45_9 -->
    <visual>
      <origin xyz="0.0255 0 -0.00945" rpy="1.5708 0 0"/>
      <geometry>
        <mesh filename="package://assets/wj_wk00_0124bottomcase_45.stl"/>
      </geometry>
      <material name="wj_wk00_0124bottomcase_45_9_material">
        <color rgba="0.247059 0.243137 0.243137 1"/>
      </material>
    </visual>
    <!-- Part wj_wk00_0122topcabinetcase_95_9 -->
    <visual>
      <origin xyz="0.0255 0 -0.00945" rpy="1.5708 0 0"/>
      <geometry>
        <mesh filename="package://assets/wj_wk00_0122topcabinetcase_95.stl"/>
      </geometry>
      <material name="wj_wk00_0122topcabinetcase_95_9_material">
        <color rgba="0.247059 0.243137 0.243137 1"/>
      </material>
    </visual>
    <!-- Part passive_palonier_9 -->
    <visual>
      <origin xyz="0.0255 0 -0.00655" rpy="1.5708 0 0"/>
      <geometry>
        <mesh filename="package://assets/passive_palonier.stl"/>
      </geometry>
      <material name="passive_palonier_9_material">
        <color rgba="0.623529 0.666667 0.701961 1"/>
      </material>
    </visual>
  </link>
  <!-- Link head_assembly -->
  <link name="head_assembly">
    <inertial>
      <origin xyz="0.00971805 -0.00384392 0.0125575" rpy="0 0 0"/>
      <mass value="0.448409"/>
      <inertia ixx="0.00275316" ixy="3.44216e-07" ixz="8.23743e-05" iyy="0.00177727" iyz="2.03389e-06" izz="0.00126711"/>
    </inertial>
    <!-- Part usb_camera_ov2710 -->
    <visual>
      <origin xyz="0.0105858 -0.06368 -0.03795" rpy="-1.5708 -0 1.5708"/>
      <geometry>
        <mesh filename="package://assets/usb_camera_ov2710.stl"/>
      </geometry>
      <material name="usb_camera_ov2710_material">
        <color rgba="0.615686 0.811765 0.929412 1"/>
      </material>
    </visual>
    <!-- Part head_bot_sheet -->
    <visual>
      <origin xyz="-0.12906 -0 0.06095" rpy="-0 1.5708 0"/>
      <geometry>
        <mesh filename="package://assets/head_bot_sheet.stl"/>
      </geometry>
      <material name="head_bot_sheet_material">
        <color rgba="0.647059 0.647059 0.647059 1"/>
      </material>
    </visual>
    <!-- Part head_2 -->
    <visual>
      <origin xyz="-0.12906 -0 0.06095" rpy="-0 1.5708 0"/>
      <geometry>
        <mesh filename="package://assets/head.stl"/>
      </geometry>
      <material name="head_2_material">
        <color rgba="0.917647 0.917647 0.917647 1"/>
      </material>
    </visual>
    <!-- Part flash_reflector_interface -->
    <visual>
      <origin xyz="-0.127863 0.00328892 0.06095" rpy="-0 1.5708 0"/>
      <geometry>
        <mesh filename="package://assets/flash_reflector_interface.stl"/>
      </geometry>
      <material name="flash_reflector_interface_material">
        <color rgba="0.647059 0.647059 0.647059 1"/>
      </material>
    </visual>
    <!-- Part bulb -->
    <visual>
      <origin xyz="-0.12906 0.01 0.06095" rpy="-0 1.5708 0"/>
      <geometry>
        <mesh filename="package://assets/bulb.stl"/>
      </geometry>
      <material name="bulb_material">
        <color rgba="0.972549 0.529412 0.00392157 1"/>
      </material>
    </visual>
    <!-- Part glass -->
    <visual>
      <origin xyz="-0.12906 0.01 0.06115" rpy="-0 1.5708 0"/>
      <geometry>
        <mesh filename="package://assets/glass.stl"/>
      </geometry>
      <material name="glass_material">
        <color rgba="0.760784 0.839216 0.92549 0.909804"/>
      </material>
    </visual>
    <!-- Part head_roll_mount -->
    <visual>
      <origin xyz="-0.12906 -0 0.06095" rpy="-0 1.5708 0"/>
      <geometry>
        <mesh filename="package://assets/head_roll_mount.stl"/>
      </geometry>
      <material name="head_roll_mount_material">
        <color rgba="0.501961 0.501961 0.501961 1"/>
      </material>
    </visual>
    <!-- Part left_eye -->
    <visual>
      <origin xyz="-0.12906 -0.01 0.06095" rpy="-0 1.5708 0"/>
      <geometry>
        <mesh filename="package://assets/left_eye.stl"/>
      </geometry>
      <material name="left_eye_material">
        <color rgba="0.498039 0.498039 0.498039 1"/>
      </material>
    </visual>
    <!-- Part flash_light_module -->
    <visual>
      <origin xyz="-0.127863 0.00328892 0.06095" rpy="-0 1.5708 0"/>
      <geometry>
        <mesh filename="package://assets/flash_light_module.stl"/>
      </geometry>
      <material name="flash_light_module_material">
        <color rgba="0.34902 0.376471 0.4 1"/>
      </material>
    </visual>
    <!-- Part full_speaker -->
    <visual>
      <origin xyz="0.00522415 -0.0588802 0.0190505" rpy="-0 1.30458 -1.32344"/>
      <geometry>
        <mesh filename="package://assets/full_speaker.stl"/>
      </geometry>
      <material name="full_speaker_material">
        <color rgba="0.647059 0.647059 0.647059 1"/>
      </material>
    </visual>
    <!-- Part roll_bearing_3 -->
    <visual>
      <origin xyz="-0 -0.035 0.167325" rpy="-0 -0 0"/>
      <geometry>
        <mesh filename="package://assets/roll_bearing.stl"/>
      </geometry>
      <material name="roll_bearing_3_material">
        <color rgba="0.6 0.6 0.6 1"/>
      </material>
    </visual>
    <!-- Part sg90 -->
    <visual>
      <origin xyz="-0.00624594 0.0331408 0.102812" rpy="-0 -1.30458 -1.81815"/>
      <geometry>
        <mesh filename="package://assets/sg90.stl"/>
      </geometry>
      <material name="sg90_material">
        <color rgba="0.435294 0.670588 0.976471 0.827451"/>
      </material>
    </visual>
    <!-- Part glass_2 -->
    <visual>
      <origin xyz="-0.12906 0.01 0.063" rpy="-0 1.5708 0"/>
      <geometry>
        <mesh filename="package://assets/glass.stl"/>
      </geometry>
      <material name="glass_2_material">
        <color rgba="0.760784 0.839216 0.92549 0.909804"/>
      </material>
    </visual>
    <!-- Part sg90_2 -->
    <visual>
      <origin xyz="-0.00624594 -0.0331408 0.102812" rpy="-2e-12 -1.30458 1.81815"/>
      <geometry>
        <mesh filename="package://assets/sg90.stl"/>
      </geometry>
      <material name="sg90_2_material">
        <color rgba="0.435294 0.670588 0.976471 0.827451"/>
      </material>
    </visual>
    <!-- Part bulb_2 -->
    <visual>
      <origin xyz="-0.12906 0.07 0.06095" rpy="-0 1.5708 0"/>
      <geometry>
        <mesh filename="package://assets/bulb.stl"/>
      </geometry>
      <material name="bulb_2_material">
        <color rgba="0.972549 0.529412 0.00392157 1"/>
      </material>
    </visual>
    <!-- Part speaker_interface -->
    <visual>
      <origin xyz="-0.12906 -0 0.06095" rpy="-0 1.5708 0"/>
      <geometry>
        <mesh filename="package://assets/speaker_interface.stl"/>
      </geometry>
      <material name="speaker_interface_material">
        <color rgba="0.615686 0.811765 0.929412 1"/>
      </material>
    </visual>
    <!-- Part speaker_stand -->
    <visual>
      <origin xyz="-0.12906 -0 0.06095" rpy="-0 1.5708 0"/>
      <geometry>
        <mesh filename="package://assets/speaker_stand.stl"/>
      </geometry>
      <material name="speaker_stand_material">
        <color rgba="0.980392 0.713725 0.00392157 1"/>
      </material>
    </visual>
    <!-- Part right_eye -->
    <visual>
      <origin xyz="-0.12906 0.01 0.06095" rpy="-0 1.5708 0"/>
      <geometry>
        <mesh filename="package://assets/right_eye.stl"/>
      </geometry>
      <material name="right_eye_material">
        <color rgba="0.34902 0.376471 0.4 1"/>
      </material>
    </visual>
    <!-- Part usb_camera_ov2710_2 -->
    <visual>
      <origin xyz="0.0105858 0.06368 -0.03805" rpy="-1.5708 -0 1.5708"/>
      <geometry>
        <mesh filename="package://assets/usb_camera_ov2710.stl"/>
      </geometry>
      <material name="usb_camera_ov2710_2_material">
        <color rgba="0.615686 0.811765 0.929412 1"/>
      </material>
    </visual>
    <!-- Part glass_3 -->
    <visual>
      <origin xyz="-0.12906 0.07 0.06515" rpy="-0 1.5708 0"/>
      <geometry>
        <mesh filename="package://assets/glass.stl"/>
      </geometry>
      <material name="glass_3_material">
        <color rgba="0.760784 0.839216 0.92549 0.909804"/>
      </material>
    </visual>
    <!-- Part glass_4 -->
    <visual>
      <origin xyz="-0.12906 0.07 0.067" rpy="-0 1.5708 0"/>
      <geometry>
        <mesh filename="package://assets/glass.stl"/>
      </geometry>
      <material name="glass_4_material">
        <color rgba="0.760784 0.839216 0.92549 0.909804"/>
      </material>
    </visual>
    <!-- Part wj_wk00_0123middlecase_56_10 -->
    <visual>
      <origin xyz="0.0255 0 -0.00945" rpy="1.5708 -0 0"/>
      <geometry>
        <mesh filename="package://assets/wj_wk00_0123middlecase_56.stl"/>
      </geometry>
      <material name="wj_wk00_0123middlecase_56_10_material">
        <color rgba="0.247059 0.243137 0.243137 1"/>
      </material>
    </visual>
    <!-- Part drive_palonier_10 -->
    <visual>
      <origin xyz="0.0255 0 -0.00945" rpy="1.5708 -0 0"/>
      <geometry>
        <mesh filename="package://assets/drive_palonier.stl"/>
      </geometry>
      <material name="drive_palonier_10_material">
        <color rgba="0.623529 0.666667 0.701961 1"/>
      </material>
    </visual>
    <!-- Part wj_wk00_0124bottomcase_45_10 -->
    <visual>
      <origin xyz="0.0255 0 -0.00945" rpy="1.5708 -0 0"/>
      <geometry>
        <mesh filename="package://assets/wj_wk00_0124bottomcase_45.stl"/>
      </geometry>
      <material name="wj_wk00_0124bottomcase_45_10_material">
        <color rgba="0.247059 0.243137 0.243137 1"/>
      </material>
    </visual>
    <!-- Part wj_wk00_0122topcabinetcase_95_10 -->
    <visual>
      <origin xyz="0.0255 0 -0.00945" rpy="1.5708 -0 0"/>
      <geometry>
        <mesh filename="package://assets/wj_wk00_0122topcabinetcase_95.stl"/>
      </geometry>
      <material name="wj_wk00_0122topcabinetcase_95_10_material">
        <color rgba="0.247059 0.243137 0.243137 1"/>
      </material>
    </visual>
    <!-- Part passive_palonier_10 -->
    <visual>
      <origin xyz="0.0255 0 -0.00655" rpy="1.5708 -0 0"/>
      <geometry>
        <mesh filename="package://assets/passive_palonier.stl"/>
      </geometry>
      <material name="passive_palonier_10_material">
        <color rgba="0.623529 0.666667 0.701961 1"/>
      </material>
    </visual>
  </link>
  <!-- Frame head (dummy link + fixed joint) -->
  <link name="head">
    <origin xyz="0 0 0" rpy="0 -0 0"/>
    <inertial>
      <origin xyz="0 0 0" rpy="0 0 0"/>
      <mass value="1e-9"/>
      <inertia ixx="0" ixy="0" ixz="0" iyy="0" iyz="0" izz="0"/>
    </inertial>
  </link>
  <joint name="head_frame" type="fixed">
    <origin xyz="0.04245 -0 0.03595" rpy="-0 1.5708 0"/>
    <parent link="head_assembly"/>
    <child link="head"/>
    <axis xyz="0 0 0"/>
  </joint>
  <!-- Link left_antenna_holder -->
  <link name="left_antenna_holder">
    <inertial>
      <origin xyz="-0.00567024 7e-11 -0.0021613" rpy="0 0 0"/>
      <mass value="0.00367319"/>
      <inertia ixx="5.06923e-07" ixy="-0" ixz="-2.043e-09" iyy="2.37902e-07" iyz="-0" izz="7.12274e-07"/>
    </inertial>
    <!-- Part left_antenna_holder -->
    <visual>
      <origin xyz="0.0296981 -0.110962 0.101994" rpy="-1.81815 -0.266217 0"/>
      <geometry>
        <mesh filename="package://assets/left_antenna_holder.stl"/>
      </geometry>
      <material name="left_antenna_holder_material">
        <color rgba="0.980392 0.713725 0.00392157 1"/>
      </material>
    </visual>
  </link>
  <!-- Joint from head_assembly to left_antenna_holder -->
  <joint name="left_antenna" type="revolute">
    <origin xyz="0.000704069 0.0606628 0.116435" rpy="-3.14159 1.30458 1.32344"/>
    <parent link="head_assembly"/>
    <child link="left_antenna_holder"/>
    <axis xyz="0 0 1"/>
    <limit effort="100" velocity="100" lower="-1.5708" upper="1.5708"/>
    <joint_properties friction="0.0"/>
  </joint>
  <!-- Link right_antenna_holder -->
  <link name="right_antenna_holder">
    <inertial>
      <origin xyz="-0.00567025 7.8e-10 -0.0021613" rpy="0 0 0"/>
      <mass value="0.00367318"/>
      <inertia ixx="5.06923e-07" ixy="-0" ixz="-2.043e-09" iyy="2.37902e-07" iyz="-0" izz="7.12273e-07"/>
    </inertial>
    <!-- Part right_antenna_holder -->
    <visual>
      <origin xyz="0.0296981 0.110962 0.101994" rpy="1.81815 -0.266217 -0"/>
      <geometry>
        <mesh filename="package://assets/right_antenna_holder.stl"/>
      </geometry>
      <material name="right_antenna_holder_material">
        <color rgba="0.980392 0.713725 0.00392157 1"/>
      </material>
    </visual>
  </link>
  <!-- Joint from head_assembly to right_antenna_holder -->
  <joint name="right_antenna" type="revolute">
    <origin xyz="0.000704069 -0.0606628 0.116435" rpy="-3.14159 1.30458 -1.32344"/>
    <parent link="head_assembly"/>
    <child link="right_antenna_holder"/>
    <axis xyz="0 0 1"/>
    <limit effort="100" velocity="100" lower="-1.5708" upper="1.5708"/>
    <joint_properties friction="0.0"/>
  </joint>
  <!-- Joint from neck_yaw_assembly to head_assembly -->
  <joint name="head_roll" type="revolute">
    <origin xyz="0.04095 0 -0.01915" rpy="0 -1.5708 0"/>
    <parent link="neck_yaw_assembly"/>
    <child link="head_assembly"/>
    <axis xyz="0 0 1"/>
    <limit effort="100" velocity="100" lower="-0.523599" upper="0.523599"/>
    <joint_properties friction="0.0"/>
  </joint>
  <!-- Joint from head_pitch_to_yaw to neck_yaw_assembly -->
  <joint name="head_yaw" type="revolute">
    <origin xyz="0 0.057 0.01905" rpy="-1.5708 0 0"/>
    <parent link="head_pitch_to_yaw"/>
    <child link="neck_yaw_assembly"/>
    <axis xyz="0 0 1"/>
    <limit effort="100" velocity="100" lower="-2.79253" upper="2.79253"/>
    <joint_properties friction="0.0"/>
  </joint>
  <!-- Joint from neck_pitch_assembly to head_pitch_to_yaw -->
  <joint name="head_pitch" type="revolute">
    <origin xyz="0 0.066 0" rpy="0 0 0"/>
    <parent link="neck_pitch_assembly"/>
    <child link="head_pitch_to_yaw"/>
    <axis xyz="0 0 1"/>
    <limit effort="100" velocity="100" lower="-0.785398" upper="0.785398"/>
    <joint_properties friction="0.0"/>
  </joint>
  <!-- Joint from trunk_assembly to neck_pitch_assembly -->
  <joint name="neck_pitch" type="revolute">
    <origin xyz="0.001 0.01915 0.0900009" rpy="1.5708 0 0"/>
    <parent link="trunk_assembly"/>
    <child link="neck_pitch_assembly"/>
    <axis xyz="0 0 1"/>
    <limit effort="100" velocity="100" lower="-0.349066" upper="1.13446"/>
    <joint_properties friction="0.0"/>
  </joint>
  <!-- Link hip_roll_assembly_2 -->
  <link name="hip_roll_assembly_2">
    <inertial>
      <origin xyz="0.000795081 -5.46541e-06 -0.03306" rpy="0 0 0"/>
      <mass value="0.06648"/>
      <inertia ixx="2.44411e-05" ixy="2.357e-09" ixz="-3.81059e-07" iyy="2.81818e-05" iyz="-7.5e-09" izz="1.42687e-05"/>
    </inertial>
    <!-- Part roll_motor_bottom_2 -->
    <visual>
      <origin xyz="-0 -0.035 0.01905" rpy="0 -0 -0"/>
      <geometry>
        <mesh filename="package://assets/roll_motor_bottom.stl"/>
      </geometry>
      <material name="roll_motor_bottom_2_material">
        <color rgba="0.647059 0.647059 0.647059 1"/>
      </material>
    </visual>
    <!-- Part roll_motor_top_2 -->
    <visual>
      <origin xyz="-0 -0.035 0.01905" rpy="0 -0 -0"/>
      <geometry>
        <mesh filename="package://assets/roll_motor_top.stl"/>
      </geometry>
      <material name="roll_motor_top_2_material">
        <color rgba="0.901961 0.901961 0.901961 1"/>
      </material>
    </visual>
    <!-- Part wj_wk00_0123middlecase_56_11 -->
    <visual>
      <origin xyz="0.0096 0 -0.020515" rpy="-1.5708 -1.5708 0"/>
      <geometry>
        <mesh filename="package://assets/wj_wk00_0123middlecase_56.stl"/>
      </geometry>
      <material name="wj_wk00_0123middlecase_56_11_material">
        <color rgba="0.247059 0.243137 0.243137 1"/>
      </material>
    </visual>
    <!-- Part drive_palonier_11 -->
    <visual>
      <origin xyz="0.0096 0 -0.020515" rpy="-1.5708 -1.5708 0"/>
      <geometry>
        <mesh filename="package://assets/drive_palonier.stl"/>
      </geometry>
      <material name="drive_palonier_11_material">
        <color rgba="0.623529 0.666667 0.701961 1"/>
      </material>
    </visual>
    <!-- Part wj_wk00_0124bottomcase_45_11 -->
    <visual>
      <origin xyz="0.0096 0 -0.020515" rpy="-1.5708 -1.5708 0"/>
      <geometry>
        <mesh filename="package://assets/wj_wk00_0124bottomcase_45.stl"/>
      </geometry>
      <material name="wj_wk00_0124bottomcase_45_11_material">
        <color rgba="0.247059 0.243137 0.243137 1"/>
      </material>
    </visual>
    <!-- Part wj_wk00_0122topcabinetcase_95_11 -->
    <visual>
      <origin xyz="0.0096 0 -0.020515" rpy="-1.5708 -1.5708 0"/>
      <geometry>
        <mesh filename="package://assets/wj_wk00_0122topcabinetcase_95.stl"/>
      </geometry>
      <material name="wj_wk00_0122topcabinetcase_95_11_material">
        <color rgba="0.247059 0.243137 0.243137 1"/>
      </material>
    </visual>
    <!-- Part passive_palonier_11 -->
    <visual>
      <origin xyz="0.0125 0 -0.020515" rpy="-1.5708 -1.5708 0"/>
      <geometry>
        <mesh filename="package://assets/passive_palonier.stl"/>
      </geometry>
      <material name="passive_palonier_11_material">
        <color rgba="0.623529 0.666667 0.701961 1"/>
      </material>
    </visual>
  </link>
  <!-- Link right_roll_to_pitch_assembly -->
  <link name="right_roll_to_pitch_assembly">
    <inertial>
      <origin xyz="-0.0507497 -0.000417205 0.0204377" rpy="0 0 0"/>
      <mass value="0.07516"/>
      <inertia ixx="2.52676e-05" ixy="-1.31172e-07" ixz="7.32857e-07" iyy="4.15738e-05" iyz="-8.9468e-08" izz="2.82863e-05"/>
    </inertial>
    <!-- Part right_roll_to_pitch -->
    <visual>
      <origin xyz="0.035 -0.065 0.01905" rpy="1.5708 1.5708 0"/>
      <geometry>
        <mesh filename="package://assets/right_roll_to_pitch.stl"/>
      </geometry>
      <material name="right_roll_to_pitch_material">
        <color rgba="0.909804 0.572549 0.164706 1"/>
      </material>
    </visual>
    <!-- Part wj_wk00_0123middlecase_56_12 -->
    <visual>
      <origin xyz="-0.0647 0 0.00961" rpy="-1.5708 1.5708 0"/>
      <geometry>
        <mesh filename="package://assets/wj_wk00_0123middlecase_56.stl"/>
      </geometry>
      <material name="wj_wk00_0123middlecase_56_12_material">
        <color rgba="0.247059 0.243137 0.243137 1"/>
      </material>
    </visual>
    <!-- Part drive_palonier_12 -->
    <visual>
      <origin xyz="-0.0647 0 0.00961" rpy="-1.5708 1.5708 0"/>
      <geometry>
        <mesh filename="package://assets/drive_palonier.stl"/>
      </geometry>
      <material name="drive_palonier_12_material">
        <color rgba="0.623529 0.666667 0.701961 1"/>
      </material>
    </visual>
    <!-- Part wj_wk00_0124bottomcase_45_12 -->
    <visual>
      <origin xyz="-0.0647 0 0.00961" rpy="-1.5708 1.5708 0"/>
      <geometry>
        <mesh filename="package://assets/wj_wk00_0124bottomcase_45.stl"/>
      </geometry>
      <material name="wj_wk00_0124bottomcase_45_12_material">
        <color rgba="0.247059 0.243137 0.243137 1"/>
      </material>
    </visual>
    <!-- Part wj_wk00_0122topcabinetcase_95_12 -->
    <visual>
      <origin xyz="-0.0647 0 0.00961" rpy="-1.5708 1.5708 0"/>
      <geometry>
        <mesh filename="package://assets/wj_wk00_0122topcabinetcase_95.stl"/>
      </geometry>
      <material name="wj_wk00_0122topcabinetcase_95_12_material">
        <color rgba="0.247059 0.243137 0.243137 1"/>
      </material>
    </visual>
    <!-- Part passive_palonier_12 -->
    <visual>
      <origin xyz="-0.0676 0 0.00961" rpy="-1.5708 1.5708 0"/>
      <geometry>
        <mesh filename="package://assets/passive_palonier.stl"/>
      </geometry>
      <material name="passive_palonier_12_material">
        <color rgba="0.623529 0.666667 0.701961 1"/>
      </material>
    </visual>
  </link>
  <!-- Link knee_and_ankle_assembly_3 -->
  <link name="knee_and_ankle_assembly_3">
    <inertial>
      <origin xyz="0.00253369 0.0390636 0.010809" rpy="0 0 0"/>
      <mass value="0.12407"/>
      <inertia ixx="0.000212363" ixy="2.68706e-05" ixz="3.9656e-06" iyy="7.93324e-05" iyz="-2.17407e-05" izz="0.000225619"/>
    </inertial>
    <!-- Part right_cache -->
    <visual>
      <origin xyz="0.01606 -0.065 0.1092" rpy="1.5708 0 -0"/>
      <geometry>
        <mesh filename="package://assets/right_cache.stl"/>
      </geometry>
      <material name="right_cache_material">
        <color rgba="0.917647 0.917647 0.917647 1"/>
      </material>
    </visual>
    <!-- Part leg_spacer_3 -->
    <visual>
      <origin xyz="0.01606 -0.14365 -0.07215" rpy="1.5708 0 0"/>
      <geometry>
        <mesh filename="package://assets/leg_spacer.stl"/>
      </geometry>
      <material name="leg_spacer_3_material">
        <color rgba="0.647059 0.647059 0.647059 1"/>
      </material>
    </visual>
    <!-- Part left_knee_to_ankle_right_sheet_3 -->
    <visual>
      <origin xyz="0.01606 -0.14365 -0.07205" rpy="1.5708 -0 -0"/>
      <geometry>
        <mesh filename="package://assets/left_knee_to_ankle_right_sheet.stl"/>
      </geometry>
      <material name="left_knee_to_ankle_right_sheet_3_material">
        <color rgba="0.223529 0.219608 0.219608 1"/>
      </material>
    </visual>
    <!-- Part left_knee_to_ankle_left_sheet_3 -->
    <visual>
      <origin xyz="0.01606 -0.14365 -0.07205" rpy="1.5708 -0 -0"/>
      <geometry>
        <mesh filename="package://assets/left_knee_to_ankle_left_sheet.stl"/>
      </geometry>
      <material name="left_knee_to_ankle_left_sheet_3_material">
        <color rgba="0.223529 0.219608 0.219608 1"/>
      </material>
    </visual>
    <!-- Part wj_wk00_0123middlecase_56_13 -->
    <visual>
      <origin xyz="-0 0.05315 0.02755" rpy="1.5708 -0 -1.5708"/>
      <geometry>
        <mesh filename="package://assets/wj_wk00_0123middlecase_56.stl"/>
      </geometry>
      <material name="wj_wk00_0123middlecase_56_13_material">
        <color rgba="0.247059 0.243137 0.243137 1"/>
      </material>
    </visual>
    <!-- Part drive_palonier_13 -->
    <visual>
      <origin xyz="-0 0.05315 0.02755" rpy="1.5708 -0 -1.5708"/>
      <geometry>
        <mesh filename="package://assets/drive_palonier.stl"/>
      </geometry>
      <material name="drive_palonier_13_material">
        <color rgba="0.623529 0.666667 0.701961 1"/>
      </material>
    </visual>
    <!-- Part wj_wk00_0124bottomcase_45_13 -->
    <visual>
      <origin xyz="-0 0.05315 0.02755" rpy="1.5708 -0 -1.5708"/>
      <geometry>
        <mesh filename="package://assets/wj_wk00_0124bottomcase_45.stl"/>
      </geometry>
      <material name="wj_wk00_0124bottomcase_45_13_material">
        <color rgba="0.247059 0.243137 0.243137 1"/>
      </material>
    </visual>
    <!-- Part wj_wk00_0122topcabinetcase_95_13 -->
    <visual>
      <origin xyz="-0 0.05315 0.02755" rpy="1.5708 -0 -1.5708"/>
      <geometry>
        <mesh filename="package://assets/wj_wk00_0122topcabinetcase_95.stl"/>
      </geometry>
      <material name="wj_wk00_0122topcabinetcase_95_13_material">
        <color rgba="0.247059 0.243137 0.243137 1"/>
      </material>
    </visual>
    <!-- Part passive_palonier_13 -->
    <visual>
      <origin xyz="-0 0.05315 0.03045" rpy="1.5708 -0 -1.5708"/>
      <geometry>
        <mesh filename="package://assets/passive_palonier.stl"/>
      </geometry>
      <material name="passive_palonier_13_material">
        <color rgba="0.623529 0.666667 0.701961 1"/>
      </material>
    </visual>
  </link>
  <!-- Link knee_and_ankle_assembly_4 -->
  <link name="knee_and_ankle_assembly_4">
    <inertial>
      <origin xyz="5.01859e-06 -0.0577465 0.0181136" rpy="0 0 0"/>
      <mass value="0.07259"/>
      <inertia ixx="4.99575e-05" ixy="1.0382e-08" ixz="2.252e-09" iyy="1.87273e-05" iyz="8.8105e-08" izz="4.23932e-05"/>
    </inertial>
    <!-- Part leg_spacer_4 -->
    <visual>
      <origin xyz="0.01606 0.14365 0.10925" rpy="-1.5708 0 0"/>
      <geometry>
        <mesh filename="package://assets/leg_spacer.stl"/>
      </geometry>
      <material name="leg_spacer_4_material">
        <color rgba="0.647059 0.647059 0.647059 1"/>
      </material>
    </visual>
    <!-- Part left_knee_to_ankle_right_sheet_4 -->
    <visual>
      <origin xyz="0.01606 0.14365 0.10915" rpy="-1.5708 0 0"/>
      <geometry>
        <mesh filename="package://assets/left_knee_to_ankle_right_sheet.stl"/>
      </geometry>
      <material name="left_knee_to_ankle_right_sheet_4_material">
        <color rgba="0.223529 0.219608 0.219608 1"/>
      </material>
    </visual>
    <!-- Part left_knee_to_ankle_left_sheet_4 -->
    <visual>
      <origin xyz="0.01606 0.14365 0.10915" rpy="-1.5708 0 -0"/>
      <geometry>
        <mesh filename="package://assets/left_knee_to_ankle_left_sheet.stl"/>
      </geometry>
      <material name="left_knee_to_ankle_left_sheet_4_material">
        <color rgba="0.223529 0.219608 0.219608 1"/>
      </material>
    </visual>
    <!-- Part wj_wk00_0123middlecase_56_14 -->
    <visual>
      <origin xyz="-0 -0.05315 0.00955" rpy="-1.5708 -0 1.5708"/>
      <geometry>
        <mesh filename="package://assets/wj_wk00_0123middlecase_56.stl"/>
      </geometry>
      <material name="wj_wk00_0123middlecase_56_14_material">
        <color rgba="0.247059 0.243137 0.243137 1"/>
      </material>
    </visual>
    <!-- Part drive_palonier_14 -->
    <visual>
      <origin xyz="-0 -0.05315 0.00955" rpy="-1.5708 -0 1.5708"/>
      <geometry>
        <mesh filename="package://assets/drive_palonier.stl"/>
      </geometry>
      <material name="drive_palonier_14_material">
        <color rgba="0.623529 0.666667 0.701961 1"/>
      </material>
    </visual>
    <!-- Part wj_wk00_0124bottomcase_45_14 -->
    <visual>
      <origin xyz="-0 -0.05315 0.00955" rpy="-1.5708 -0 1.5708"/>
      <geometry>
        <mesh filename="package://assets/wj_wk00_0124bottomcase_45.stl"/>
      </geometry>
      <material name="wj_wk00_0124bottomcase_45_14_material">
        <color rgba="0.247059 0.243137 0.243137 1"/>
      </material>
    </visual>
    <!-- Part wj_wk00_0122topcabinetcase_95_14 -->
    <visual>
      <origin xyz="-0 -0.05315 0.00955" rpy="-1.5708 -0 1.5708"/>
      <geometry>
        <mesh filename="package://assets/wj_wk00_0122topcabinetcase_95.stl"/>
      </geometry>
      <material name="wj_wk00_0122topcabinetcase_95_14_material">
        <color rgba="0.247059 0.243137 0.243137 1"/>
      </material>
    </visual>
    <!-- Part passive_palonier_14 -->
    <visual>
      <origin xyz="0 -0.05315 0.00665" rpy="-1.5708 -0 1.5708"/>
      <geometry>
        <mesh filename="package://assets/passive_palonier.stl"/>
      </geometry>
      <material name="passive_palonier_14_material">
        <color rgba="0.623529 0.666667 0.701961 1"/>
      </material>
    </visual>
  </link>
  <!-- Link foot_assembly_2 -->
  <link name="foot_assembly_2">
    <inertial>
      <origin xyz="0.0110718 -0.0246608 0.0190626" rpy="0 0 0"/>
      <mass value="0.07524"/>
      <inertia ixx="1.87482e-05" ixy="1.58839e-06" ixz="-6.524e-09" iyy="6.74427e-05" iyz="5.6739e-08" izz="6.061e-05"/>
    </inertial>
    <!-- Part foot_side_2 -->
    <visual>
      <origin xyz="0.01606 0.2223 0.10905" rpy="-1.5708 0 0"/>
      <geometry>
        <mesh filename="package://assets/foot_side.stl"/>
      </geometry>
      <material name="foot_side_2_material">
        <color rgba="0.980392 0.713725 0.00392157 1"/>
      </material>
    </visual>
    <!-- Part foot_bottom_tpu_2 -->
    <visual>
      <origin xyz="0.01656 0.2228 0.10955" rpy="-1.5708 0 0"/>
      <geometry>
        <mesh filename="package://assets/foot_bottom_tpu.stl"/>
      </geometry>
      <material name="foot_bottom_tpu_2_material">
        <color rgba="0.305882 0.298039 0.278431 1"/>
      </material>
    </visual>
    <collision>
      <origin xyz="0.01656 0.2228 0.10955" rpy="-1.5708 0 0"/>
      <geometry>
        <mesh filename="package://assets/foot_bottom_tpu.stl"/>
      </geometry>
    </collision>
    <!-- Part foot_bottom_pla_2 -->
    <visual>
      <origin xyz="0.01656 0.2228 0.10955" rpy="-1.5708 0 0"/>
      <geometry>
        <mesh filename="package://assets/foot_bottom_pla.stl"/>
      </geometry>
      <material name="foot_bottom_pla_2_material">
        <color rgba="0.305882 0.298039 0.278431 1"/>
      </material>
    </visual>
    <!-- Part foot_top_2 -->
    <visual>
      <origin xyz="0.01606 0.2223 0.10905" rpy="-1.5708 0 0"/>
      <geometry>
        <mesh filename="package://assets/foot_top.stl"/>
      </geometry>
      <material name="foot_top_2_material">
        <color rgba="0.980392 0.713725 0.00392157 1"/>
      </material>
    </visual>
  </link>
  <!-- Frame right_foot (dummy link + fixed joint) -->
  <link name="right_foot">
    <origin xyz="0 0 0" rpy="0 -0 0"/>
    <inertial>
      <origin xyz="0 0 0" rpy="0 0 0"/>
      <mass value="1e-9"/>
      <inertia ixx="0" ixy="0" ixz="0" iyy="0" iyz="0" izz="0"/>
    </inertial>
  </link>
  <joint name="right_foot_frame" type="fixed">
    <origin xyz="0.0005 -0.036225 0.01955" rpy="-1.5708 0 -0"/>
    <parent link="foot_assembly_2"/>
    <child link="right_foot"/>
    <axis xyz="0 0 0"/>
  </joint>
  <!-- Joint from knee_and_ankle_assembly_4 to foot_assembly_2 -->
  <joint name="right_ankle" type="revolute">
    <origin xyz="0 -0.07865 0.0001" rpy="0 0 0"/>
    <parent link="knee_and_ankle_assembly_4"/>
    <child link="foot_assembly_2"/>
    <axis xyz="0 0 1"/>
    <limit effort="100" velocity="100" lower="-1.5708" upper="1.5708"/>
    <joint_properties friction="0.0"/>
  </joint>
  <!-- Joint from knee_and_ankle_assembly_3 to knee_and_ankle_assembly_4 -->
  <joint name="right_knee" type="revolute">
    <origin xyz="0 0.07865 0.037" rpy="3.14159 0 0"/>
    <parent link="knee_and_ankle_assembly_3"/>
    <child link="knee_and_ankle_assembly_4"/>
    <axis xyz="0 0 1"/>
    <limit effort="100" velocity="100" lower="-1.5708" upper="1.5708"/>
    <joint_properties friction="0.0"/>
  </joint>
  <!-- Joint from right_roll_to_pitch_assembly to knee_and_ankle_assembly_3 -->
  <joint name="right_hip_pitch" type="revolute">
    <origin xyz="-0.07415 0 0.03511" rpy="0 1.5708 0"/>
    <parent link="right_roll_to_pitch_assembly"/>
    <child link="knee_and_ankle_assembly_3"/>
    <axis xyz="0 0 1"/>
    <limit effort="100" velocity="100" lower="-0.5236" upper="1.2217"/>
    <joint_properties friction="0.0"/>
  </joint>
  <!-- Joint from hip_roll_assembly_2 to right_roll_to_pitch_assembly -->
  <joint name="right_hip_roll" type="revolute">
    <origin xyz="0.01905 0 -0.046015" rpy="-1.5708 0 1.5708"/>
    <parent link="hip_roll_assembly_2"/>
    <child link="right_roll_to_pitch_assembly"/>
    <axis xyz="0 0 1"/>
    <limit effort="100" velocity="100" lower="-0.436332" upper="0.436332"/>
    <joint_properties friction="0.0"/>
  </joint>
  <!-- Joint from trunk_assembly to hip_roll_assembly_2 -->
  <joint name="right_hip_yaw" type="revolute">
    <origin xyz="-0.019 -0.035 0.0459409" rpy="0 0 0"/>
    <parent link="trunk_assembly"/>
    <child link="hip_roll_assembly_2"/>
    <axis xyz="0 0 1"/>
    <limit effort="100" velocity="100" lower="-0.523599" upper="0.523599"/>
    <joint_properties friction="0.0"/>
  </joint>
</robot>
